Workbook

Sheet Léeme
A1: Resultados — FloodNet (U-Net híbrido, DeepLabV3+, YOLO11n-seg)
A2: Cómo leer este libro
A4: HOJAS
A5: Resumen | B5: Métricas globales de test de los tres modelos, estadísticas por imagen, entrenamiento y una comprobación frente a las cifras de los cuadernos. En verde, el mejor de cada fila.
A6: Por clase | B6: IoU, Dice, precisión y recall de cada clase sobre todo el test, los tres modelos lado a lado.
A7: Distribución de clases | B7: Representación de cada clase en todo el dataset usado (2.247 imágenes, no solo test): % de píxeles y de imágenes por partición, parte de la imagen que ocupa cuando aparece, IoU de test de los tres modelos y correlación de Spearman entre ambas.
A8: Comparación por imagen | B8: Una fila por imagen de test con Mean_IoU, precisión, recall y pixel accuracy de los tres modelos, el mejor modelo y la diferencia entre el mejor y el peor. Admite filtros.
A9: U-Net / DeepLabV3+ / YOLO11n-seg | B9: Una fila por imagen: IoU, precisión y recall de cada clase y el resumen de la imagen. Los bloques por clase se pueden plegar con los botones [1] [2] de la esquina.
A10: Parámetros | B10: Arquitectura, entrenamiento e inferencia de cada modelo.
A11: DEFINICIONES
A12: IoU de una clase | B12: TP / (TP + FP + FN) en píxeles. Vacía si la clase no está ni en la referencia ni en la predicción.
A13: Precisión de una clase | B13: TP / (TP + FP): de los píxeles que el modelo asigna a la clase, cuántos son correctos. Vacía si el modelo no predice la clase en esa imagen.
A14: Recall de una clase | B14: TP / (TP + FN): de los píxeles de la clase en la referencia, cuántos encuentra el modelo. Vacío si la clase no está en la referencia.
A15: Precisión / Recall / Mean_IoU | B15: Media de la métrica sobre las clases con valor en esa imagen (celdas vacías fuera). Son fórmulas: se recalculan si se cambia algún valor por clase.
A16: Pixel accuracy | B16: Píxeles bien clasificados / total de píxeles de la imagen.
A17: % píxeles sin predicción | B17: Solo YOLO: píxeles que ninguna instancia cubre. Cuentan como error (FN) de su clase real.
A18: mIoU global ≠ media por imagen | B18: El mIoU de la hoja Resumen acumula los píxeles de todo el test y divide una vez (como los cuadernos). La media de Mean_IoU por imagen pesa igual cada imagen y suele salir más baja: en una imagen, una clase con pocos píxeles mal segmentada baja mucho su media.
A19: Por qué YOLO gana en la media por imagen | B19: En la media por imagen, cada clase que el modelo predice y no está en la referencia suma un IoU de 0. El U-Net deja de media 0,51 clases espurias por imagen, DeepLabV3+ 0,42 y YOLO 0,33, porque YOLO descarta las detecciones poco seguras. A cambio YOLO se salta más clases reales (0,18 por imagen, frente a 0,10 del U-Net), que pesan poco en esa media pero sí en el mIoU global.
A20: ORIGEN DE LOS DATOS
A21: Imágenes | B21: Las 426 imágenes de la partición test oficial de FloodNet-Supervised v1.0 que no tienen una máscara de una sola clase, reducidas a 512×512 (data/cache512_full). Mismas imágenes para los tres modelos. La hoja «Distribución de clases» usa además las de train y val: 2.247 imágenes en total.
A22: Inferencia | B22: Recalculada en CPU con los checkpoints entrenados y la misma configuración que cada cuaderno: U-Net con TTA de 4 volteos (best_model_iou_full.pth), DeepLabV3+ con su ONNX y YOLO con best.pt, conf 0,25. El mIoU global coincide con el de los cuadernos a 4 decimales (ver Resumen, Comprobación).
A23: Referencias | B23: Las máscaras de test son las oficiales, que tienen errores de anotación (sobre todo agua/hierba). Las cifras absolutas están afectadas por ese ruido; la comparación entre modelos es justa.

Sheet Resumen
A1: FloodNet — resultados de test de las tres arquitecturas
A2: Test oficial de FloodNet-Supervised v1.0 sin máscaras de una sola clase: 426 imágenes a 512×512.
B3: Matriz de confusión acumulada sobre todo el test
A4: Métrica (test completo) | B4: U-Net | C4: DeepLabV3+ | D4: YOLO11n-seg | E4: Mejor
A5: mIoU (10 clases) | B5: 0.73145947 | C5: 0.70935146 | D5: 0.70491346 | E5: =INDEX($B$4:$D$4,MATCH(MAX(B5:D5),B5:D5,0))
A6: mIoU (sin Background) | B6: 0.75431374 | C6: 0.7381444 | D6: 0.73947243 | E6: =INDEX($B$4:$D$4,MATCH(MAX(B6:D6),B6:D6,0))
A7: Dice medio (10 clases) | B7: 0.84057968 | C7: 0.8227507 | D7: 0.8184974 | E7: =INDEX($B$4:$D$4,MATCH(MAX(B7:D7),B7:D7,0))
A8: Dice medio (sin Background) | B8: 0.85740106 | C8: 0.8451792 | D8: 0.84664611 | E8: =INDEX($B$4:$D$4,MATCH(MAX(B8:D8),B8:D8,0))
A9: Precisión (media por clase) | B9: 0.85499432 | C9: 0.8212877 | D9: 0.83368162 | E9: =INDEX($B$4:$D$4,MATCH(MAX(B9:D9),B9:D9,0))
A10: Recall (media por clase) | B10: 0.83611164 | C10: 0.83117645 | D10: 0.81388296 | E10: =INDEX($B$4:$D$4,MATCH(MAX(B10:D10),B10:D10,0))
A11: Pixel accuracy | B11: 0.90993853 | C11: 0.90769877 | D11: 0.88984115 | E11: =INDEX($B$4:$D$4,MATCH(MAX(B11:D11),B11:D11,0))
A12: % píxeles sin predicción | B12: 0 | C12: 0 | D12: 0.029910558 | E12: =IF(COUNTIF(B12:D12,MIN(B12:D12))>1,"Empate",INDEX($B$4:$D$4,MATCH(MIN(B12:D12),B12:D12,0)))
B14: Estadísticas por imagen (a partir de la hoja Comparación por imagen)
A15: Métrica | B15: U-Net | C15: DeepLabV3+ | D15: YOLO11n-seg | E15: Mejor
A16: Mean_IoU medio por imagen | B16: =AVERAGE('Comparación por imagen'!B5:B430) | C16: =AVERAGE('Comparación por imagen'!C5:C430) | D16: =AVERAGE('Comparación por imagen'!D5:D430) | E16: =INDEX($B$15:$D$15,MATCH(MAX(B16:D16),B16:D16,0))
A17: Mean_IoU mediano por imagen | B17: =MEDIAN('Comparación por imagen'!B5:B430) | C17: =MEDIAN('Comparación por imagen'!C5:C430) | D17: =MEDIAN('Comparación por imagen'!D5:D430) | E17: =INDEX($B$15:$D$15,MATCH(MAX(B17:D17),B17:D17,0))
A18: Mean_IoU mínimo (peor imagen) | B18: =MIN('Comparación por imagen'!B5:B430) | C18: =MIN('Comparación por imagen'!C5:C430) | D18: =MIN('Comparación por imagen'!D5:D430) | E18: =INDEX($B$15:$D$15,MATCH(MAX(B18:D18),B18:D18,0))
A19: Precisión media por imagen | B19: =AVERAGE('Comparación por imagen'!G5:G430) | C19: =AVERAGE('Comparación por imagen'!H5:H430) | D19: =AVERAGE('Comparación por imagen'!I5:I430) | E19: =INDEX($B$15:$D$15,MATCH(MAX(B19:D19),B19:D19,0))
A20: Recall medio por imagen | B20: =AVERAGE('Comparación por imagen'!J5:J430) | C20: =AVERAGE('Comparación por imagen'!K5:K430) | D20: =AVERAGE('Comparación por imagen'!L5:L430) | E20: =INDEX($B$15:$D$15,MATCH(MAX(B20:D20),B20:D20,0))
A21: Imágenes en las que es el mejor (Mean_IoU) | B21: =COUNTIF('Comparación por imagen'!E5:E430,"U-Net") | C21: =COUNTIF('Comparación por imagen'!E5:E430,"DeepLabV3+") | D21: =COUNTIF('Comparación por imagen'!E5:E430,"YOLO11n-seg") | E21: =INDEX($B$15:$D$15,MATCH(MAX(B21:D21),B21:D21,0))
A22: % de imágenes en las que es el mejor | B22: =B21/426 | C22: =C21/426 | D22: =D21/426
B24: Modelo y entrenamiento (detalle en la hoja Parámetros)
A25: Parámetros | B25: 86680082 | C25: 26679898 | D25: 2851654
A26: Épocas ejecutadas | B26: 30 | C26: 40 | D26: 235
A27: Mejor época (val) | B27: 30 | C27: 32 | D27: 185
A28: Tiempo de entrenamiento (h, RTX 4060 Laptop) | B28: 2.25 | C28: 0.775 | D28: 2.612
A29: TTA en test | B29: Sí (4 volteos) | C29: No | D29: No
B31: Comprobación: mIoU recalculado (CPU) frente al reportado en el cuaderno (GPU)
B32: U-Net | C32: DeepLabV3+ | D32: YOLO11n-seg
A33: mIoU reportado por el cuaderno | B33: 0.7315 | C33: 0.70934008 | D33: 0.70484637
A34: mIoU recalculado en este Excel | B34: =B5 | C34: =C5 | D34: =D5
A35: Diferencia | B35: =B34-B33 | C35: =C34-C33 | D35: =D34-D33

Sheet Por clase
A1: Métricas por clase sobre el test completo (426 imágenes)
A2: Calculadas sobre la matriz de confusión acumulada de todo el test, como en los cuadernos. En verde, el mejor modelo de cada métrica y clase.
B3: IoU | E3: Dice | H3: Precisión | K3: Recall | N3: IoU
A4: Clase | B4: U-Net | C4: DeepLabV3+ | D4: YOLO11n-seg | E4: U-Net | F4: DeepLabV3+ | G4: YOLO11n-seg | H4: U-Net | I4: DeepLabV3+ | J4: YOLO11n-seg | K4: U-Net | L4: DeepLabV3+ | M4: YOLO11n-seg | N4: Mejor IoU
A5: Background | B5: 0.52577098 | C5: 0.45021502 | D5: 0.39388268 | E5: 0.68918729 | F5: 0.62089416 | G5: 0.56515901 | H5: 0.89173638 | I5: 0.73451703 | J5: 0.7764281 | K5: 0.5616207 | L5: 0.53771476 | M5: 0.44427112 | N5: =INDEX($B$4:$D$4,MATCH(MAX(B5:D5),B5:D5,0))
A6: Building-flooded | B6: 0.70728789 | C6: 0.71070758 | D6: 0.72673137 | E6: 0.82855141 | F6: 0.83089312 | G6: 0.84174224 | H6: 0.79968471 | I6: 0.78556753 | J6: 0.80238254 | K6: 0.85958019 | L6: 0.88176935 | M6: 0.88516261 | N6: =INDEX($B$4:$D$4,MATCH(MAX(B6:D6),B6:D6,0))
A7: Building-non-flooded | B7: 0.80567284 | C7: 0.79958149 | D7: 0.79420297 | E7: 0.89237964 | F7: 0.88863049 | G7: 0.88529891 | H7: 0.90201487 | I7: 0.90150483 | J7: 0.90531357 | K7: 0.88294809 | L7: 0.87611869 | M7: 0.86615009 | N7: =INDEX($B$4:$D$4,MATCH(MAX(B7:D7),B7:D7,0))
A8: Road-flooded | B8: 0.66623079 | C8: 0.61210413 | D8: 0.63938291 | E8: 0.79968609 | F8: 0.75938535 | G8: 0.78002876 | H8: 0.73402266 | I8: 0.67656589 | J8: 0.75915721 | K8: 0.87825182 | L8: 0.86530917 | M8: 0.80208039 | N8: =INDEX($B$4:$D$4,MATCH(MAX(B8:D8),B8:D8,0))
A9: Road-non-flooded | B9: 0.83260235 | C9: 0.83136577 | D9: 0.80871636 | E9: 0.90865577 | F9: 0.90791887 | G9: 0.89424343 | H9: 0.90578963 | I9: 0.90179331 | J9: 0.90449853 | K9: 0.91154011 | L9: 0.91412822 | M9: 0.88421827 | N9: =INDEX($B$4:$D$4,MATCH(MAX(B9:D9),B9:D9,0))
A10: Water | B10: 0.7718318 | C10: 0.75652223 | D10: 0.76671756 | E10: 0.87122469 | F10: 0.86138646 | G10: 0.86795714 | H10: 0.8988815 | I10: 0.87320105 | J10: 0.88849718 | K10: 0.84521896 | L10: 0.84988731 | M10: 0.84834532 | N10: =INDEX($B$4:$D$4,MATCH(MAX(B10:D10),B10:D10,0))
A11: Tree | B11: 0.81513973 | C11: 0.8309559 | D11: 0.83136881 | E11: 0.89815645 | F11: 0.9076744 | G11: 0.90792068 | H11: 0.92126574 | I11: 0.92220443 | J11: 0.90228378 | K11: 0.87617815 | L11: 0.89359514 | M11: 0.91362846 | N11: =INDEX($B$4:$D$4,MATCH(MAX(B11:D11),B11:D11,0))
A12: Vehicle | B12: 0.62597585 | C12: 0.56954245 | D12: 0.56593094 | E12: 0.76996943 | F12: 0.72574329 | G12: 0.72280447 | H12: 0.73372078 | I12: 0.67553851 | J12: 0.67616788 | K12: 0.80998587 | L12: 0.78400943 | M12: 0.77635087 | N12: =INDEX($B$4:$D$4,MATCH(MAX(B12:D12),B12:D12,0))
A13: Pool | B13: 0.67990977 | C13: 0.64714453 | D13: 0.65123798 | E13: 0.80945987 | F13: 0.78577747 | G13: 0.78878755 | H13: 0.83981058 | I13: 0.80805466 | J13: 0.774741 | K13: 0.78122639 | L13: 0.76469565 | M13: 0.80335286 | N13: =INDEX($B$4:$D$4,MATCH(MAX(B13:D13),B13:D13,0))
A14: Grass | B14: 0.88417267 | C14: 0.88537546 | D14: 0.870963 | E14: 0.93852616 | F14: 0.93920334 | G14: 0.93103178 | H14: 0.92301636 | I14: 0.93392975 | J14: 0.94734639 | K14: 0.9545661 | L14: 0.94453682 | M14: 0.91526957 | N14: =INDEX($B$4:$D$4,MATCH(MAX(B14:D14),B14:D14,0))
A15: Media (macro) | B15: =AVERAGE(B5:B14) | C15: =AVERAGE(C5:C14) | D15: =AVERAGE(D5:D14) | E15: =AVERAGE(E5:E14) | F15: =AVERAGE(F5:F14) | G15: =AVERAGE(G5:G14) | H15: =AVERAGE(H5:H14) | I15: =AVERAGE(I5:I14) | ... M15: =AVERAGE(M5:M14)
A17: La fila «Media (macro)» de IoU es el mIoU de 10 clases de la hoja Resumen.

Sheet Distribución de clases
A1: Representación de cada clase en el dataset frente a la IoU de test
A2: Máscaras 512×512 de data/cache512_full: las 2.247 imágenes de FloodNet-Supervised v1.0 sin máscara de una sola clase (train 1.387 · val 434 · test 426). Generada por la sección 6.5 de floodnet-segmentation.ipynb.
B4: Píxeles | G4: Imágenes en que aparece | J4: Parte de la imagen cuando aparece | L4: IoU test
A5: Clase | B5: Nº train | C5: % train | D5: % val | E5: % test | F5: % global | G5: Nº train | H5: % train | I5: % global | J5: Media | K5: Mediana | L5: U-Net | M5: DeepLabV3+ | N5: YOLO11n-seg
A6: Grass | B6: 201695526 | C6: 0.55472774 | D6: 0.53001502 | E6: 0.53849417 | F6: 0.54687691 | G6: 1305 | H6: 0.9408796 | I6: 0.9341344 | J6: 0.58543707 | K6: 0.58216095 | L6: =INDEX('Por clase'!$B$5:$B$14,MATCH($A6,'Por clase'!$A$5:$A$14,0)) | M6: =INDEX('Por clase'!$C$5:$C$14,MATCH($A6,'Por clase'!$A$5:$A$14,0)) | N6: =INDEX('Por clase'!$D$5:$D$14,MATCH($A6,'Por clase'!$A$5:$A$14,0))
A7: Tree | B7: 65862555 | C7: 0.18114326 | D7: 0.19339817 | E7: 0.18773699 | F7: 0.18476033 | G7: 1155 | H7: 0.83273252 | I7: 0.83711615 | J7: 0.22071051 | K7: 0.19119644 | L7: =INDEX('Por clase'!$B$5:$B$14,MATCH($A7,'Por clase'!$A$5:$A$14,0)) | M7: =INDEX('Por clase'!$C$5:$C$14,MATCH($A7,'Por clase'!$A$5:$A$14,0)) | N7: =INDEX('Por clase'!$D$5:$D$14,MATCH($A7,'Por clase'!$A$5:$A$14,0))
A8: Water | B8: 39812323 | C8: 0.10949673 | D8: 0.11473599 | E8: 0.10796807 | F8: 0.11021886 | G8: 699 | H8: 0.50396539 | I8: 0.48420116 | J8: 0.22763031 | K8: 0.16127968 | L8: =INDEX('Por clase'!$B$5:$B$14,MATCH($A8,'Por clase'!$A$5:$A$14,0)) | M8: =INDEX('Por clase'!$C$5:$C$14,MATCH($A8,'Por clase'!$A$5:$A$14,0)) | N8: =INDEX('Por clase'!$D$5:$D$14,MATCH($A8,'Por clase'!$A$5:$A$14,0))
A9: Road-non-flooded | B9: 21268759 | C9: 0.058495946 | D9: 0.061023624 | E9: 0.06322002 | F9: 0.059879777 | G9: 729 | H9: 0.52559481 | I9: 0.53093013 | J9: 0.11278278 | K9: 0.096839905 | L9: =INDEX('Por clase'!$B$5:$B$14,MATCH($A9,'Por clase'!$A$5:$A$14,0)) | M9: =INDEX('Por clase'!$C$5:$C$14,MATCH($A9,'Por clase'!$A$5:$A$14,0)) | N9: =INDEX('Por clase'!$D$5:$D$14,MATCH($A9,'Por clase'!$A$5:$A$14,0))
A10: Building-non-flooded | B10: 12188603 | C10: 0.033522589 | D10: 0.029870978 | E10: 0.036078887 | F10: 0.033301932 | G10: 547 | H10: 0.39437635 | I10: 0.39474855 | J10: 0.084362391 | K10: 0.057666779 | L10: =INDEX('Por clase'!$B$5:$B$14,MATCH($A10,'Por clase'!$A$5:$A$14,0)) | M10: =INDEX('Por clase'!$C$5:$C$14,MATCH($A10,'Por clase'!$A$5:$A$14,0)) | N10: =INDEX('Por clase'!$D$5:$D$14,MATCH($A10,'Por clase'!$A$5:$A$14,0))
A11: Road-flooded | B11: 9974433 | C11: 0.027432907 | D11: 0.025745717 | E11: 0.023205457 | F11: 0.026305567 | G11: 162 | H11: 0.11679885 | I11: 0.11748999 | J11: 0.22389624 | K11: 0.17288399 | L11: =INDEX('Por clase'!$B$5:$B$14,MATCH($A11,'Por clase'!$A$5:$A$14,0)) | M11: =INDEX('Por clase'!$C$5:$C$14,MATCH($A11,'Por clase'!$A$5:$A$14,0)) | N11: =INDEX('Por clase'!$D$5:$D$14,MATCH($A11,'Por clase'!$A$5:$A$14,0))
A12: Building-flooded | B12: 6139265 | C12: 0.016884958 | D12: 0.018028417 | E12: 0.017232474 | F12: 0.017171698 | G12: 152 | H12: 0.10958904 | I12: 0.11036938 | J12: 0.15558389 | K12: 0.16564941 | L12: =INDEX('Por clase'!$B$5:$B$14,MATCH($A12,'Por clase'!$A$5:$A$14,0)) | M12: =INDEX('Por clase'!$C$5:$C$14,MATCH($A12,'Por clase'!$A$5:$A$14,0)) | N12: =INDEX('Por clase'!$D$5:$D$14,MATCH($A12,'Por clase'!$A$5:$A$14,0))
A13: Background | B13: 5198925 | C13: 0.01429872 | D13: 0.023477625 | E13: 0.022422361 | F13: 0.017611722 | G13: 103 | H13: 0.074260995 | I13: 0.078771696 | J13: 0.22357932 | K13: 0.13486481 | L13: =INDEX('Por clase'!$B$5:$B$14,MATCH($A13,'Por clase'!$A$5:$A$14,0)) | M13: =INDEX('Por clase'!$C$5:$C$14,MATCH($A13,'Por clase'!$A$5:$A$14,0)) | N13: =INDEX('Por clase'!$D$5:$D$14,MATCH($A13,'Por clase'!$A$5:$A$14,0))
A14: Pool | B14: 766260 | C14: 0.0021074621 | D14: 0.0019469898 | E14: 0.0019555338 | F14: 0.002047664 | G14: 335 | H14: 0.24152848 | I14: 0.23809524 | J14: 0.0086001886 | K14: 0.0067481995 | L14: =INDEX('Por clase'!$B$5:$B$14,MATCH($A14,'Por clase'!$A$5:$A$14,0)) | M14: =INDEX('Por clase'!$C$5:$C$14,MATCH($A14,'Por clase'!$A$5:$A$14,0)) | N14: =INDEX('Por clase'!$D$5:$D$14,MATCH($A14,'Por clase'!$A$5:$A$14,0))
A15: Vehicle | B15: 687079 | C15: 0.0018896888 | D15: 0.0017574679 | E15: 0.0016860425 | F15: 0.0018255423 | G15: 505 | H15: 0.36409517 | I15: 0.36582109 | J15: 0.0049902598 | K15: 0.0037021637 | L15: =INDEX('Por clase'!$B$5:$B$14,MATCH($A15,'Por clase'!$A$5:$A$14,0)) | M15: =INDEX('Por clase'!$C$5:$C$14,MATCH($A15,'Por clase'!$A$5:$A$14,0)) | N15: =INDEX('Por clase'!$D$5:$D$14,MATCH($A15,'Por clase'!$A$5:$A$14,0))
A16: Total | B16: =SUM(B6:B15) | C16: =SUM(C6:C15) | D16: =SUM(D6:D15) | E16: =SUM(E6:E15) | F16: =SUM(F6:F15)
A18: % píxeles: parte de todos los píxeles de la partición que son de la clase. Como todas las máscaras miden 512×512, coincide con la media por imagen del % que ocupa la clase.
A19: Imágenes en que aparece: imágenes con al menos un píxel de la clase. Es el recuento que usan el oversampling y los pesos de la pérdida.
A20: Parte de la imagen cuando aparece: % de la imagen que ocupa la clase, solo en las imágenes en que aparece. Separa las clases escasas (salen en pocas fotos) de las pequeñas (salen a menudo y ocupan poco).
A21: IoU test: fórmulas enlazadas a la hoja «Por clase» (426 imágenes de test).
A23: Correlación de Spearman entre la representación en train y la IoU de test
A24: Variable | B24: Clases | C24: n | D24: ρ U-Net | E24: ρ DeepLabV3+ | F24: ρ YOLO11n-seg | G24: p U-Net | H24: p DeepLabV3+ | I24: p YOLO11n-seg
A25: % píxeles train | B25: 10 clases | C25: 10 | D25: 0.85454545 | E25: 0.85454545 | F25: 0.87878788 | G25: 0.0016368033 | H25: 0.0016368033 | I25: 0.00081386211
A26: % píxeles train | B26: sin Background | C26: 9 | D26: 0.86666667 | E26: 0.86666667 | F26: 0.9 | G26: 0.0024953983 | H26: 0.0024953983 | I26: 0.00094306232
A27: % imágenes train | B27: 10 clases | C27: 10 | D27: 0.86666667 | E27: 0.86666667 | F27: 0.87878788 | G27: 0.0011735382 | H27: 0.0011735382 | I27: 0.00081386211
A28: % imágenes train | B28: sin Background | C28: 9 | D28: 0.81666667 | E28: 0.81666667 | F28: 0.83333333 | G28: 0.0072247852 | H28: 0.0072247852 | I28: 0.005265691
A29: % medio cuando aparece | B29: 10 clases | C29: 10 | D29: 0.27272727 | E29: 0.27272727 | F29: 0.2969697 | G29: 0.44583834 | H29: 0.44583834 | I29: 0.40470167
A30: % medio cuando aparece | B30: sin Background | C30: 9 | D30: 0.48333333 | E30: 0.48333333 | F30: 0.51666667 | G30: 0.18746986 | H30: 0.18746986 | I30: 0.15439012
A31: Con 10 clases, |ρ| ≥ 0,65 es significativo al 5 % (0,70 con 9). Correlación no implica causa: las clases con pocos píxeles suelen ser también objetos pequeños o de borde ambiguo.

Sheet Comparación por imagen
A1: Comparación de las tres arquitecturas, imagen a imagen
A2: Cada valor se lee de la hoja del modelo. «Mejor modelo» es el de mayor Mean_IoU en esa imagen.
B3: Mean_IoU | E3: Mean_IoU | G3: Precisión | J3: Recall | M3: Pixel accuracy
A4: Imagen | B4: U-Net | C4: DeepLabV3+ | D4: YOLO11n-seg | E4: Mejor modelo | F4: Diferencia mejor − peor | G4: U-Net | H4: DeepLabV3+ | I4: YOLO11n-seg | J4: U-Net | K4: DeepLabV3+ | L4: YOLO11n-seg | M4: U-Net | N4: DeepLabV3+ | O4: YOLO11n-seg
A5: ='U-Net'!A5 | B5: ='U-Net'!AH5 | C5: ='DeepLabV3+'!AH5 | D5: ='YOLO11n-seg'!AH5 | E5: =INDEX($B$4:$D$4,MATCH(MAX(B5:D5),B5:D5,0)) | F5: =MAX(B5:D5)-MIN(B5:D5) | G5: ='U-Net'!AF5 | H5: ='DeepLabV3+'!AF5 | I5: ='YOLO11n-seg'!AF5 | J5: ='U-Net'!AG5 | K5: ='DeepLabV3+'!AG5 | L5: ='YOLO11n-seg'!AG5 | M5: ='U-Net'!AI5 | N5: ='DeepLabV3+'!AI5 | O5: ='YOLO11n-seg'!AI5
A6: ='U-Net'!A6 | B6: ='U-Net'!AH6 | C6: ='DeepLabV3+'!AH6 | D6: ='YOLO11n-seg'!AH6 | E6: =INDEX($B$4:$D$4,MATCH(MAX(B6:D6),B6:D6,0)) | F6: =MAX(B6:D6)-MIN(B6:D6) | G6: ='U-Net'!AF6 | H6: ='DeepLabV3+'!AF6 | I6: ='YOLO11n-seg'!AF6 | J6: ='U-Net'!AG6 | K6: ='DeepLabV3+'!AG6 | L6: ='YOLO11n-seg'!AG6 | M6: ='U-Net'!AI6 | N6: ='DeepLabV3+'!AI6 | O6: ='YOLO11n-seg'!AI6
A7: ='U-Net'!A7 | B7: ='U-Net'!AH7 | C7: ='DeepLabV3+'!AH7 | D7: ='YOLO11n-seg'!AH7 | E7: =INDEX($B$4:$D$4,MATCH(MAX(B7:D7),B7:D7,0)) | F7: =MAX(B7:D7)-MIN(B7:D7) | G7: ='U-Net'!AF7 | H7: ='DeepLabV3+'!AF7 | I7: ='YOLO11n-seg'!AF7 | J7: ='U-Net'!AG7 | K7: ='DeepLabV3+'!AG7 | L7: ='YOLO11n-seg'!AG7 | M7: ='U-Net'!AI7 | N7: ='DeepLabV3+'!AI7 | O7: ='YOLO11n-seg'!AI7
A8: ='U-Net'!A8 | B8: ='U-Net'!AH8 | C8: ='DeepLabV3+'!AH8 | D8: ='YOLO11n-seg'!AH8 | E8: =INDEX($B$4:$D$4,MATCH(MAX(B8:D8),B8:D8,0)) | F8: =MAX(B8:D8)-MIN(B8:D8) | G8: ='U-Net'!AF8 | H8: ='DeepLabV3+'!AF8 | I8: ='YOLO11n-seg'!AF8 | J8: ='U-Net'!AG8 | K8: ='DeepLabV3+'!AG8 | L8: ='YOLO11n-seg'!AG8 | M8: ='U-Net'!AI8 | N8: ='DeepLabV3+'!AI8 | O8: ='YOLO11n-seg'!AI8
A9: ='U-Net'!A9 | B9: ='U-Net'!AH9 | C9: ='DeepLabV3+'!AH9 | D9: ='YOLO11n-seg'!AH9 | E9: =INDEX($B$4:$D$4,MATCH(MAX(B9:D9),B9:D9,0)) | F9: =MAX(B9:D9)-MIN(B9:D9) | G9: ='U-Net'!AF9 | H9: ='DeepLabV3+'!AF9 | I9: ='YOLO11n-seg'!AF9 | J9: ='U-Net'!AG9 | K9: ='DeepLabV3+'!AG9 | L9: ='YOLO11n-seg'!AG9 | M9: ='U-Net'!AI9 | N9: ='DeepLabV3+'!AI9 | O9: ='YOLO11n-seg'!AI9
A10: ='U-Net'!A10 | B10: ='U-Net'!AH10 | C10: ='DeepLabV3+'!AH10 | D10: ='YOLO11n-seg'!AH10 | E10: =INDEX($B$4:$D$4,MATCH(MAX(B10:D10),B10:D10,0)) | F10: =MAX(B10:D10)-MIN(B10:D10) | G10: ='U-Net'!AF10 | H10: ='DeepLabV3+'!AF10 | I10: ='YOLO11n-seg'!AF10 | J10: ='U-Net'!AG10 | K10: ='DeepLabV3+'!AG10 | L10: ='YOLO11n-seg'!AG10 | M10: ='U-Net'!AI10 | N10: ='DeepLabV3+'!AI10 | O10: ='YOLO11n-seg'!AI10
A11: ='U-Net'!A11 | B11: ='U-Net'!AH11 | C11: ='DeepLabV3+'!AH11 | D11: ='YOLO11n-seg'!AH11 | E11: =INDEX($B$4:$D$4,MATCH(MAX(B11:D11),B11:D11,0)) | F11: =MAX(B11:D11)-MIN(B11:D11) | G11: ='U-Net'!AF11 | H11: ='DeepLabV3+'!AF11 | I11: ='YOLO11n-seg'!AF11 | J11: ='U-Net'!AG11 | K11: ='DeepLabV3+'!AG11 | L11: ='YOLO11n-seg'!AG11 | M11: ='U-Net'!AI11 | N11: ='DeepLabV3+'!AI11 | O11: ='YOLO11n-seg'!AI11
A12: ='U-Net'!A12 | B12: ='U-Net'!AH12 | C12: ='DeepLabV3+'!AH12 | D12: ='YOLO11n-seg'!AH12 | E12: =INDEX($B$4:$D$4,MATCH(MAX(B12:D12),B12:D12,0)) | F12: =MAX(B12:D12)-MIN(B12:D12) | G12: ='U-Net'!AF12 | H12: ='DeepLabV3+'!AF12 | I12: ='YOLO11n-seg'!AF12 | J12: ='U-Net'!AG12 | K12: ='DeepLabV3+'!AG12 | L12: ='YOLO11n-seg'!AG12 | M12: ='U-Net'!AI12 | N12: ='DeepLabV3+'!AI12 | O12: ='YOLO11n-seg'!AI12
A13: ='U-Net'!A13 | B13: ='U-Net'!AH13 | C13: ='DeepLabV3+'!AH13 | D13: ='YOLO11n-seg'!AH13 | E13: =INDEX($B$4:$D$4,MATCH(MAX(B13:D13),B13:D13,0)) | F13: =MAX(B13:D13)-MIN(B13:D13) | G13: ='U-Net'!AF13 | H13: ='DeepLabV3+'!AF13 | I13: ='YOLO11n-seg'!AF13 | J13: ='U-Net'!AG13 | K13: ='DeepLabV3+'!AG13 | L13: ='YOLO11n-seg'!AG13 | M13: ='U-Net'!AI13 | N13: ='DeepLabV3+'!AI13 | O13: ='YOLO11n-seg'!AI13
A14: ='U-Net'!A14 | B14: ='U-Net'!AH14 | C14: ='DeepLabV3+'!AH14 | D14: ='YOLO11n-seg'!AH14 | E14: =INDEX($B$4:$D$4,MATCH(MAX(B14:D14),B14:D14,0)) | F14: =MAX(B14:D14)-MIN(B14:D14) | G14: ='U-Net'!AF14 | H14: ='DeepLabV3+'!AF14 | I14: ='YOLO11n-seg'!AF14 | J14: ='U-Net'!AG14 | K14: ='DeepLabV3+'!AG14 | L14: ='YOLO11n-seg'!AG14 | M14: ='U-Net'!AI14 | N14: ='DeepLabV3+'!AI14 | O14: ='YOLO11n-seg'!AI14
A15: ='U-Net'!A15 | B15: ='U-Net'!AH15 | C15: ='DeepLabV3+'!AH15 | D15: ='YOLO11n-seg'!AH15 | E15: =INDEX($B$4:$D$4,MATCH(MAX(B15:D15),B15:D15,0)) | F15: =MAX(B15:D15)-MIN(B15:D15) | G15: ='U-Net'!AF15 | H15: ='DeepLabV3+'!AF15 | I15: ='YOLO11n-seg'!AF15 | J15: ='U-Net'!AG15 | K15: ='DeepLabV3+'!AG15 | L15: ='YOLO11n-seg'!AG15 | M15: ='U-Net'!AI15 | N15: ='DeepLabV3+'!AI15 | O15: ='YOLO11n-seg'!AI15
A16: ='U-Net'!A16 | B16: ='U-Net'!AH16 | C16: ='DeepLabV3+'!AH16 | D16: ='YOLO11n-seg'!AH16 | E16: =INDEX($B$4:$D$4,MATCH(MAX(B16:D16),B16:D16,0)) | F16: =MAX(B16:D16)-MIN(B16:D16) | G16: ='U-Net'!AF16 | H16: ='DeepLabV3+'!AF16 | I16: ='YOLO11n-seg'!AF16 | J16: ='U-Net'!AG16 | K16: ='DeepLabV3+'!AG16 | L16: ='YOLO11n-seg'!AG16 | M16: ='U-Net'!AI16 | N16: ='DeepLabV3+'!AI16 | O16: ='YOLO11n-seg'!AI16
... A430: ='U-Net'!A430 | B430: ='U-Net'!AH430 | C430: ='DeepLabV3+'!AH430 | D430: ='YOLO11n-seg'!AH430 | E430: =INDEX($B$4:$D$4,MATCH(MAX(B430:D430),B430:D430,0)) | F430: =MAX(B430:D430)-MIN(B430:D430) | G430: ='U-Net'!AF430 | H430: ='DeepLabV3+'!AF430 | I430: ='YOLO11n-seg'!AF430 | J430: ='U-Net'!AG430 | K430: ='DeepLabV3+'!AG430 | L430: ='YOLO11n-seg'!AG430 | M430: ='U-Net'!AI430 | N430: ='DeepLabV3+'!AI430 | O430: ='YOLO11n-seg'!AI430

Sheet U-Net
A1: U-Net — métricas por imagen de test (426 imágenes)
A2: Celdas vacías: la clase no aparece ni en la referencia ni en la predicción (IoU), no se predice (precisión) o no está en la referencia (recall). Ver la hoja Léeme.
B3: IoU por clase | L3: Precisión por clase | V3: Recall por clase | AF3: Resumen de la imagen
A4: Imagen | B4: IoU Background | C4: IoU Building-flooded | D4: IoU Building-non-flooded | E4: IoU Road-flooded | F4: IoU Road-non-flooded | G4: IoU Water | H4: IoU Tree | I4: IoU Vehicle | J4: IoU Pool | K4: IoU Grass | L4: Precisión Background | M4: Precisión Building-flooded | N4: Precisión Building-non-flooded | O4: Precisión Road-flooded | P4: Precisión Road-non-flooded | Q4: Precisión Water | R4: Precisión Tree | S4: Precisión Vehicle | T4: Precisión Pool | U4: Precisión Grass | V4: Recall Background | W4: Recall Building-flooded | X4: Recall Building-non-flooded | Y4: Recall Road-flooded | Z4: Recall Road-non-flooded | AA4: Recall Water | AB4: Recall Tree | AC4: Recall Vehicle | AD4: Recall Pool | AE4: Recall Grass | AF4: Precisión | AG4: Recall | AH4: Mean_IoU | AI4: Pixel accuracy | AJ4: % píxeles sin predicción
A5: 6336.jpg | F5: 0.94104846 | G5: 0.86995465 | I5: 0.78801843 | K5: 0.96660893 | P5: 0.97642983 | Q5: 0.89050078 | S5: 0.82211538 | U5: 0.98481871 | Z5: 0.96292229 | AA5: 0.97416365 | AC5: 0.95 | AE5: 0.98122982 | AF5: =IFERROR(AVERAGE(L5:U5),"") | AG5: =IFERROR(AVERAGE(V5:AE5),"") | AH5: =IFERROR(AVERAGE(B5:K5),"") | AI5: 0.97616196 | AJ5: 0
A6: 6342.jpg | F6: 0.94422169 | G6: 0.91487492 | K6: 0.97477763 | P6: 0.97345481 | Q6: 0.99385839 | U6: 0.98045676 | Z6: 0.96917607 | AA6: 0.92007659 | AE6: 0.99409289 | AF6: =IFERROR(AVERAGE(L6:U6),"") | AG6: =IFERROR(AVERAGE(V6:AE6),"") | AH6: =IFERROR(AVERAGE(B6:K6),"") | AI6: 0.98111343 | AJ6: 0
A7: 6353.jpg | F7: 0.91023985 | G7: 0.92244134 | H7: 0.7587769 | K7: 0.97272247 | P7: 0.94665643 | Q7: 0.97712742 | R7: 0.8375 | U7: 0.98480698 | Z7: 0.95945158 | AA7: 0.94279871 | AB7: 0.88977424 | AE7: 0.98754211 | AF7: =IFERROR(AVERAGE(L7:U7),"") | AG7: =IFERROR(AVERAGE(V7:AE7),"") | AH7: =IFERROR(AVERAGE(B7:K7),"") | AI7: 0.97850037 | AJ7: 0
A8: 6362.jpg | F8: 0.94497532 | G8: 0.97280749 | H8: 0.66501487 | I8: 0.68164794 | K8: 0.98646158 | P8: 0.97394339 | Q8: 0.99532004 | R8: 0.70706006 | S8: 0.69201521 | U8: 0.99286781 | Z8: 0.96948547 | AA8: 0.97727766 | AB8: 0.91792066 | AC8: 0.97849462 | AE8: 0.9935017 | AF8: =IFERROR(AVERAGE(L8:U8),"") | AG8: =IFERROR(AVERAGE(V8:AE8),"") | AH8: =IFERROR(AVERAGE(B8:K8),"") | AI8: 0.98853683 | AJ8: 0
A9: 6371.jpg | F9: 0.95111596 | G9: 0.95878008 | H9: 0 | K9: 0.98612536 | P9: 0.98700318 | Q9: 0.98906231 | R9: 0 | U9: 0.99042476 | Z9: 0.96317907 | AA9: 0.96905479 | AE9: 0.99561725 | AF9: =IFERROR(AVERAGE(L9:U9),"") | AG9: =IFERROR(AVERAGE(V9:AE9),"") | AH9: =IFERROR(AVERAGE(B9:K9),"") | AI9: 0.98906326 | AJ9: 0
A10: 6377.jpg | F10: 0.95696836 | G10: 0.95777194 | I10: 0.77819549 | K10: 0.98623685 | P10: 0.978351 | Q10: 0.99229689 | S10: 0.81818182 | U10: 0.99141408 | Z10: 0.97767137 | AA10: 0.96494641 | AC10: 0.94090909 | AE10: 0.99473295 | AF10: =IFERROR(AVERAGE(L10:U10),"") | AG10: =IFERROR(AVERAGE(V10:AE10),"") | AH10: =IFERROR(AVERAGE(B10:K10),"") | AI10: 0.98931885 | AJ10: 0
A11: 6383.jpg | F11: 0.9452325 | G11: 0.95926267 | I11: 0.69387755 | K11: 0.98787086 | P11: 0.96548857 | Q11: 0.98611966 | S11: 0.79439252 | U11: 0.99419248 | Z11: 0.97828623 | AA11: 0.97239221 | AC11: 0.84577114 | AE11: 0.99360454 | AF11: =IFERROR(AVERAGE(L11:U11),"") | AG11: =IFERROR(AVERAGE(V11:AE11),"") | AH11: =IFERROR(AVERAGE(B11:K11),"") | AI11: 0.9899559 | AJ11: 0
A12: 6389.jpg | F12: 0.94762886 | G12: 0.96314853 | H12: 0 | I12: 0 | K12: 0.98589024 | P12: 0.99475594 | Q12: 0.99627046 | R12: 0 | S12: 0 | U12: 0.98750871 | Z12: 0.95238662 | AA12: 0.96663377 | AE12: 0.99834037 | AF12: =IFERROR(AVERAGE(L12:U12),"") | AG12: =IFERROR(AVERAGE(V12:AE12),"") | AH12: =IFERROR(AVERAGE(B12:K12),"") | AI12: 0.98839951 | AJ12: 0
A13: 6391.jpg | F13: 0.95692315 | G13: 0.94107326 | K13: 0.98432227 | P13: 0.97889321 | Q13: 0.99438636 | U13: 0.98942698 | Z13: 0.97708338 | AA13: 0.94609957 | AE13: 0.9947859 | AF13: =IFERROR(AVERAGE(L13:U13),"") | AG13: =IFERROR(AVERAGE(V13:AE13),"") | AH13: =IFERROR(AVERAGE(B13:K13),"") | AI13: 0.98803711 | AJ13: 0
A14: 6394.jpg | F14: 0.79427955 | G14: 0.95766807 | K14: 0.93527101 | P14: 0.98283176 | Q14: 0.98722252 | U14: 0.9397928 | Z14: 0.8054549 | AA14: 0.9696873 | AE14: 0.99488187 | AF14: =IFERROR(AVERAGE(L14:U14),"") | AG14: =IFERROR(AVERAGE(V14:AE14),"") | AH14: =IFERROR(AVERAGE(B14:K14),"") | AI14: 0.94970703 | AJ14: 0
A15: 6405.jpg | F15: 0.92651837 | G15: 0.91698179 | K15: 0.98635835 | P15: 0.93257862 | Q15: 0.9717194 | U15: 0.99376484 | Z15: 0.99303509 | AA15: 0.94212477 | AE15: 0.99250063 | AF15: =IFERROR(AVERAGE(L15:U15),"") | AG15: =IFERROR(AVERAGE(V15:AE15),"") | AH15: =IFERROR(AVERAGE(B15:K15),"") | AI15: 0.98822784 | AJ15: 0
A16: 6412.jpg | C16: 0 | D16: 0 | F16: 0.95330003 | G16: 0 | H16: 0.77769057 | I16: 0.75471698 | J16: 0.89767157 | K16: 0.92343963 | N16: 0 | P16: 0.96240544 | Q16: 0 | R16: 0.88617131 | S16: 0.91872792 | T16: 0.94091201 | U16: 0.96108092 | W16: 0 | Z16: 0.99017296 | AB16: 0.8639992 | AC16: 0.80870918 | AD16: 0.9512987 | AE16: 0.95931294 | AF16: =IFERROR(AVERAGE(L16:U16),"") | AG16: =IFERROR(AVERAGE(V16:AE16),"") | AH16: =IFERROR(AVERAGE(B16:K16),"") | AI16: 0.70920944 | AJ16: 0
A17: 6417.jpg | D17: 0.87518587 | F17: 0.90609314 | G17: 0.87295476 | H17: 0.92035862 | I17: 0.85926141 | J17: 0.91383812 | K17: 0.90844428 | N17: 0.89353829 | P17: 0.92732863 | Q17: 0.88834476 | R17: 0.96156694 | S17: 0.93779752 | T17: 0.92592593 | U17: 0.96443769 | X17: 0.97706993 | Z17: 0.97535003 | AA17: 0.98054054 | AB17: 0.95550793 | AC17: 0.91119334 | AD17: 0.98591549 | AE17: 0.9399297 | AF17: =IFERROR(AVERAGE(L17:U17),"") | AG17: =IFERROR(AVERAGE(V17:AE17),"") | AH17: =IFERROR(AVERAGE(B17:K17),"") | AI17: 0.95208359 | AJ17: 0
A18: 6419.jpg | D18: 0.90554851 | F18: 0.91325843 | G18: 0.87154742 | H18: 0.89933768 | I18: 0.85531026 | K18: 0.93803848 | N18: 0.93141398 | P18: 0.94606968 | Q18: 0.97760358 | R18: 0.95497448 | S18: 0.92245817 | U18: 0.97151184 | X18: 0.97024583 | Z18: 0.96341367 | AA18: 0.8893039 | AB18: 0.93916027 | AC18: 0.92156863 | AE18: 0.96457053 | AF18: =IFERROR(AVERAGE(L18:U18),"") | AG18: =IFERROR(AVERAGE(V18:AE18),"") | AH18: =IFERROR(AVERAGE(B18:K18),"") | AI18: 0.95841217 | AJ18: 0
A19: 6420.jpg | B19: 0 | D19: 0.86467102 | F19: 0.93374595 | G19: 0.87414002 | H19: 0.89733559 | I19: 0.89196676 | K19: 0.9456999 | L19: 0 | N19: 0.9094013 | P19: 0.95399323 | Q19: 0.88962109 | R19: 0.96955568 | S19: 0.93333333 | U19: 0.96725421 | X19: 0.94617704 | Z19: 0.97777551 | AA19: 0.98048116 | AB19: 0.92335251 | AC19: 0.95266272 | AE19: 0.97697894 | AF19: =IFERROR(AVERAGE(L19:U19),"") | AG19: =IFERROR(AVERAGE(V19:AE19),"") | AH19: =IFERROR(AVERAGE(B19:K19),"") | AI19: 0.95940018 | AJ19: 0
A20: 6445.jpg | D20: 0.88909878 | F20: 0.36477695 | G20: 0.99243283 | H20: 0.66049859 | I20: 0.724 | J20: 0.94595843 | K20: 0.92401313 | N20: 0.91289629 | P20: 0.65717874 | Q20: 0.99249531 | R20: 0.7613123 | S20: 0.74731627 | T20: 0.98131289 | U20: 0.97076936 | X20: 0.97151542 | Z20: 0.45050215 | AA20: 0.99993657 | AB20: 0.83299571 | AC20: 0.95868644 | AD20: 0.96331138 | AE20: 0.9504575 | AF20: =IFERROR(AVERAGE(L20:U20),"") | AG20: =IFERROR(AVERAGE(V20:AE20),"") | AH20: =IFERROR(AVERAGE(B20:K20),"") | AI20: 0.95546341 | AJ20: 0
A21: 6449.jpg | D21: 0.86825661 | G21: 0.98939529 | H21: 0.8864237 | J21: 0.68482785 | K21: 0.96064616 | N21: 0.98674399 | Q21: 0.99996568 | R21: 0.9388582 | T21: 0.93977155 | U21: 0.9709321 | X21: 0.87850369 | AA21: 0.98942889 | AB21: 0.94072926 | AD21: 0.71626435 | AE21: 0.98909242 | AF21: =IFERROR(AVERAGE(L21:U21),"") | AG21: =IFERROR(AVERAGE(V21:AE21),"") | AH21: =IFERROR(AVERAGE(B21:K21),"") | AI21: 0.97757339 | AJ21: 0
A22: 6452.jpg | D22: 0.84340106 | G22: 0.99078458 | H22: 0.85338781 | I22: 0 | J22: 0.87478185 | K22: 0.94908823 | N22: 0.98039138 | Q22: 0.99997857 | R22: 0.90301794 | T22: 0.90560072 | U22: 0.95870015 | X22: 0.85787225 | AA22: 0.99080562 | AB22: 0.93949423 | AC22: 0 | AD22: 0.96255401 | AE22: 0.98954662 | AF22: =IFERROR(AVERAGE(L22:U22),"") | AG22: =IFERROR(AVERAGE(V22:AE22),"") | AH22: =IFERROR(AVERAGE(B22:K22),"") | AI22: 0.97242737 | AJ22: 0
A23: 6467.jpg | D23: 0.89095893 | F23: 0.83011856 | G23: 0.92457588 | H23: 0.84928484 | I23: 0.83523874 | J23: 0.67829852 | K23: 0.86677316 | N23: 0.95412707 | P23: 0.85555353 | Q23: 0.98534083 | R23: 0.93034291 | S23: 0.9059081 | T23: 0.80441021 | U23: 0.92347095 | X23: 0.93083196 | Z23: 0.96542498 | AA23: 0.93747094 | AB23: 0.90695645 | AC23: 0.91458027 | AD23: 0.81226171 | AE23: 0.93385217 | AF23: =IFERROR(AVERAGE(L23:U23),"") | AG23: =IFERROR(AVERAGE(V23:AE23),"") | AH23: =IFERROR(AVERAGE(B23:K23),"") | AI23: 0.92723083 | AJ23: 0
A24: 6468.jpg | D24: 0.87772995 | F24: 0.7215157 | G24: 0.97341731 | H24: 0.78664956 | I24: 0.82970489 | J24: 0.75911296 | K24: 0.89846058 | N24: 0.92458708 | P24: 0.76310733 | Q24: 0.98811382 | R24: 0.86045072 | S24: 0.86747597 | T24: 0.83275049 | U24: 0.96106667 | X24: 0.94541308 | Z24: 0.92976589 | AA24: 0.98495048 | AB24: 0.90168685 | AC24: 0.9501385 | AD24: 0.89566639 | AE24: 0.93239715 | AF24: =IFERROR(AVERAGE(L24:U24),"") | AG24: =IFERROR(AVERAGE(V24:AE24),"") | AH24: =IFERROR(AVERAGE(B24:K24),"") | AI24: 0.93822861 | AJ24: 0
A25: 6476.jpg | D25: 0.75736439 | F25: 0 | G25: 0.9395313 | H25: 0.91768519 | I25: 0 | J25: 0.4272541 | K25: 0.89858289 | N25: 0.80611118 | P25: 0 | Q25: 0.97491874 | R25: 0.93673797 | S25: 0 | T25: 0.52321205 | U25: 0.96530944 | X25: 0.92605907 | AA25: 0.96280308 | AB25: 0.97831666 | AD25: 0.69966443 | AE25: 0.92856878 | AF25: =IFERROR(AVERAGE(L25:U25),"") | AG25: =IFERROR(AVERAGE(V25:AE25),"") | AH25: =IFERROR(AVERAGE(B25:K25),"") | AI25: 0.94441986 | AJ25: 0
A26: 6488.jpg | D26: 0.66313214 | G26: 0.99065786 | H26: 0.90018149 | K26: 0.97176496 | N26: 0.75674837 | Q26: 0.99724468 | R26: 0.93692698 | U26: 0.98721512 | X26: 0.84277816 | AA26: 0.99337685 | AB26: 0.95825087 | AE26: 0.9841503 | AF26: =IFERROR(AVERAGE(L26:U26),"") | AG26: =IFERROR(AVERAGE(V26:AE26),"") | AH26: =IFERROR(AVERAGE(B26:K26),"") | AI26: 0.98381424 | AJ26: 0
A27: 6514.jpg | B27: 0 | D27: 0.77878519 | G27: 0 | H27: 0.9737962 | K27: 0.91358363 | L27: 0 | N27: 0.83274576 | Q27: 0 | R27: 0.98539936 | U27: 0.97818858 | X27: 0.92318677 | AB27: 0.98805252 | AE27: 0.93258113 | AF27: =IFERROR(AVERAGE(L27:U27),"") | AG27: =IFERROR(AVERAGE(V27:AE27),"") | AH27: =IFERROR(AVERAGE(B27:K27),"") | AI27: 0.96660614 | AJ27: 0
A28: 6517.jpg | B28: 0 | D28: 0.82968768 | G28: 0.5730897 | H28: 0.97481327 | K28: 0.90739061 | L28: 0 | N28: 0.93612248 | Q28: 0.66073871 | R28: 0.98466029 | U28: 0.95288796 | X28: 0.87947923 | AA28: 0.81203766 | AB28: 0.98984536 | AE28: 0.95001055 | AF28: =IFERROR(AVERAGE(L28:U28),"") | AG28: =IFERROR(AVERAGE(V28:AE28),"") | AH28: =IFERROR(AVERAGE(B28:K28),"") | AI28: 0.96611786 | AJ28: 0
A29: 6536.jpg | D29: 0 | F29: 0.87337794 | G29: 0.3129853 | H29: 0.88184999 | I29: 0.84556407 | K29: 0.81411669 | N29: 0 | P29: 0.91967944 | Q29: 0.6217501 | R29: 0.91916912 | S29: 0.88735632 | U29: 0.89910669 | Z29: 0.94549747 | AA29: 0.38659669 | AB29: 0.95598581 | AC29: 0.94723926 | AE29: 0.89596897 | AF29: =IFERROR(AVERAGE(L29:U29),"") | AG29: =IFERROR(AVERAGE(V29:AE29),"") | AH29: =IFERROR(AVERAGE(B29:K29),"") | AI29: 0.89821243 | AJ29: 0
A30: 6545.jpg | D30: 0.94247502 | G30: 0.73318236 | H30: 0.96613521 | K30: 0.93949745 | N30: 0.94935887 | Q30: 0.84133293 | R30: 0.99238256 | U30: 0.94762244 | X30: 0.99236512 | AA30: 0.85082702 | AB30: 0.97335357 | AE30: 0.9909563 | AF30: =IFERROR(AVERAGE(L30:U30),"") | AG30: =IFERROR(AVERAGE(V30:AE30),"") | AH30: =IFERROR(AVERAGE(B30:K30),"") | AI30: 0.97536087 | AJ30: 0
A31: 6550.jpg | F31: 0.75548546 | G31: 0.78860165 | H31: 0.81561273 | K31: 0.82666879 | P31: 0.95295494 | Q31: 0.92066033 | R31: 0.84175715 | U31: 0.92738476 | Z31: 0.78475401 | AA31: 0.84610212 | AB31: 0.96331597 | AE31: 0.88388162 | AF31: =IFERROR(AVERAGE(L31:U31),"") | AG31: =IFERROR(AVERAGE(V31:AE31),"") | AH31: =IFERROR(AVERAGE(B31:K31),"") | AI31: 0.89762497 | AJ31: 0
A32: 6553.jpg | D32: 0.74459893 | G32: 0.82788337 | H32: 0.90532609 | J32: 0.65250111 | K32: 0.86612 | N32: 0.79005901 | Q32: 0.94896279 | R32: 0.95592832 | T32: 0.65686275 | U32: 0.92009735 | X32: 0.92826667 | AA32: 0.8664629 | AB32: 0.94475914 | AD32: 0.98992612 | AE32: 0.93656381 | AF32: =IFERROR(AVERAGE(L32:U32),"") | AG32: =IFERROR(AVERAGE(V32:AE32),"") | AH32: =IFERROR(AVERAGE(B32:K32),"") | AI32: 0.93555069 | AJ32: 0
A33: 6557.jpg | D33: 0.90869221 | F33: 0 | G33: 0.87087807 | H33: 0.92602274 | I33: 0.81135225 | J33: 0.85814455 | K33: 0.89642531 | N33: 0.95025161 | P33: 0 | Q33: 0.93486314 | R33: 0.96607402 | S33: 0.98780488 | T33: 0.96191052 | U33: 0.94790057 | X33: 0.95408033 | AA33: 0.92713542 | AB33: 0.95714872 | AC33: 0.81956155 | AD33: 0.88833054 | AE33: 0.94288126 | AF33: =IFERROR(AVERAGE(L33:U33),"") | AG33: =IFERROR(AVERAGE(V33:AE33),"") | AH33: =IFERROR(AVERAGE(B33:K33),"") | AI33: 0.94893646 | AJ33: 0
A34: 6558.jpg | D34: 0.92141966 | F34: 0 | G34: 0.83498639 | H34: 0.91233061 | I34: 0.84668508 | J34: 0.70889018 | K34: 0.84898115 | N34: 0.9579723 | P34: 0 | Q34: 0.90351431 | R34: 0.94360594 | S34: 0.92458522 | T34: 0.77264091 | U34: 0.95824262 | X34: 0.96023634 | AA34: 0.91672894 | AB34: 0.9649441 | AC34: 0.90949555 | AD34: 0.89574156 | AE34: 0.88159678 | AF34: =IFERROR(AVERAGE(L34:U34),"") | AG34: =IFERROR(AVERAGE(V34:AE34),"") | AH34: =IFERROR(AVERAGE(B34:K34),"") | AI34: 0.9255867 | AJ34: 0
A35: 6561.jpg | D35: 0.8554269 | F35: 0.87394229 | G35: 0.64626297 | H35: 0.89257012 | I35: 0.75043178 | J35: 0.68268268 | K35: 0.78031338 | N35: 0.95160708 | P35: 0.9178651 | Q35: 0.74129878 | R35: 0.96088759 | S35: 0.91570074 | T35: 0.9179004 | U35: 0.85454254 | X35: 0.89433194 | Z35: 0.94808693 | AA35: 0.83446404 | AB35: 0.9262212 | AC35: 0.80612245 | AD35: 0.72707889 | AE35: 0.89983113 | AF35: =IFERROR(AVERAGE(L35:U35),"") | AG35: =IFERROR(AVERAGE(V35:AE35),"") | AH35: =IFERROR(AVERAGE(B35:K35),"") | AI35: 0.91791153 | AJ35: 0
A36: 6562.jpg | D36: 0.91488958 | F36: 0.89495409 | G36: 0.60120846 | H36: 0.93047848 | I36: 0.5819209 | J36: 0.85221239 | K36: 0.83820674 | N36: 0.98299389 | P36: 0.92138242 | Q36: 0.64204449 | R36: 0.947239 | S36: 0.7559633 | T36: 0.93586006 | U36: 0.95611639 | X36: 0.92960324 | Z36: 0.96894523 | AA36: 0.90432911 | AB36: 0.98133877 | AC36: 0.71652174 | AD36: 0.90507519 | AE36: 0.87174434 | AF36: =IFERROR(AVERAGE(L36:U36),"") | AG36: =IFERROR(AVERAGE(V36:AE36),"") | AH36: =IFERROR(AVERAGE(B36:K36),"") | AI36: 0.94155884 | AJ36: 0
A37: 6567.jpg | D37: 0.80182565 | F37: 0.92045772 | H37: 0.96423806 | K37: 0.90095042 | N37: 0.8151615 | P37: 0.98154762 | R37: 0.98498531 | U37: 0.96459751 | X37: 0.98000483 | Z37: 0.93666572 | AB37: 0.97862226 | AE37: 0.93176051 | AF37: =IFERROR(AVERAGE(L37:U37),"") | AG37: =IFERROR(AVERAGE(V37:AE37),"") | AH37: =IFERROR(AVERAGE(B37:K37),"") | AI37: 0.96203613 | AJ37: 0
A38: 6568.jpg | D38: 0.78569342 | F38: 0.92772163 | H38: 0.93248123 | I38: 0.8429003 | J38: 0.81909548 | K38: 0.88339948 | N38: 0.80845388 | P38: 0.96474657 | R38: 0.97020089 | S38: 0.8913738 | T38: 1 | U38: 0.95105501 | X38: 0.96540739 | Z38: 0.96027542 | AB38: 0.95997548 | AC38: 0.93939394 | AD38: 0.81909548 | AE38: 0.92547449 | AF38: =IFERROR(AVERAGE(L38:U38),"") | AG38: =IFERROR(AVERAGE(V38:AE38),"") | AH38: =IFERROR(AVERAGE(B38:K38),"") | AI38: 0.94609833 | AJ38: 0
A39: 6583.jpg | B39: 0 | G39: 0.70644612 | H39: 0.93019587 | K39: 0.95905225 | L39: 0 | Q39: 0.99577509 | R39: 0.98556351 | U39: 0.96628223 | AA39: 0.70856994 | AB39: 0.94304531 | AE39: 0.99225866 | AF39: =IFERROR(AVERAGE(L39:U39),"") | AG39: =IFERROR(AVERAGE(V39:AE39),"") | AH39: =IFERROR(AVERAGE(B39:K39),"") | AI39: 0.9481926 | AJ39: 0
A40: 6590.jpg | G40: 0.84787358 | K40: 0.97382524 | Q40: 0.92487183 | U40: 0.98550378 | AA40: 0.91058907 | AE40: 0.98797745 | AF40: =IFERROR(AVERAGE(L40:U40),"") | AG40: =IFERROR(AVERAGE(V40:AE40),"") | AH40: =IFERROR(AVERAGE(B40:K40),"") | AI40: 0.97715759 | AJ40: 0
...

Sheet DeepLabV3+
A1: DeepLabV3+ — métricas por imagen de test (426 imágenes)
A2: Celdas vacías: la clase no aparece ni en la referencia ni en la predicción (IoU), no se predice (precisión) o no está en la referencia (recall). Ver la hoja Léeme.
B3: IoU por clase | L3: Precisión por clase | V3: Recall por clase | AF3: Resumen de la imagen
A4: Imagen | B4: IoU Background | C4: IoU Building-flooded | D4: IoU Building-non-flooded | E4: IoU Road-flooded | F4: IoU Road-non-flooded | G4: IoU Water | H4: IoU Tree | I4: IoU Vehicle | J4: IoU Pool | K4: IoU Grass | L4: Precisión Background | M4: Precisión Building-flooded | N4: Precisión Building-non-flooded | O4: Precisión Road-flooded | P4: Precisión Road-non-flooded | Q4: Precisión Water | R4: Precisión Tree | S4: Precisión Vehicle | T4: Precisión Pool | U4: Precisión Grass | V4: Recall Background | W4: Recall Building-flooded | X4: Recall Building-non-flooded | Y4: Recall Road-flooded | Z4: Recall Road-non-flooded | AA4: Recall Water | AB4: Recall Tree | AC4: Recall Vehicle | AD4: Recall Pool | AE4: Recall Grass | AF4: Precisión | AG4: Recall | AH4: Mean_IoU | AI4: Pixel accuracy | AJ4: % píxeles sin predicción
A5: 6336.jpg | F5: 0.94414003 | G5: 0.85686992 | I5: 0.76934985 | K5: 0.96569567 | P5: 0.97015902 | Q5: 0.85949734 | S5: 0.82421227 | U5: 0.99008239 | Z5: 0.97237856 | AA5: 0.99644512 | AC5: 0.92037037 | AE5: 0.97512841 | AF5: =IFERROR(AVERAGE(L5:U5),"") | AG5: =IFERROR(AVERAGE(V5:AE5),"") | AH5: =IFERROR(AVERAGE(B5:K5),"") | AI5: 0.97560883 | AJ5: 0
A6: 6342.jpg | F6: 0.93090169 | G6: 0.9312372 | K6: 0.9750023 | P6: 0.96742102 | Q6: 0.9923638 | U6: 0.98202254 | Z6: 0.96102914 | AA6: 0.93795846 | AE6: 0.99272132 | AF6: =IFERROR(AVERAGE(L6:U6),"") | AG6: =IFERROR(AVERAGE(V6:AE6),"") | AH6: =IFERROR(AVERAGE(B6:K6),"") | AI6: 0.9813118 | AJ6: 0
A7: 6353.jpg | F7: 0.90142304 | G7: 0.92510658 | H7: 0.71401985 | K7: 0.97121021 | P7: 0.93771199 | Q7: 0.97781191 | R7: 0.91567224 | U7: 0.9839836 | Z7: 0.95883573 | AA7: 0.94494293 | AB7: 0.76427623 | AE7: 0.98681018 | AF7: =IFERROR(AVERAGE(L7:U7),"") | AG7: =IFERROR(AVERAGE(V7:AE7),"") | AH7: =IFERROR(AVERAGE(B7:K7),"") | AI7: 0.97739792 | AJ7: 0
A8: 6362.jpg | F8: 0.93519151 | G8: 0.97606364 | H8: 0.67811379 | I8: 0.65873016 | K8: 0.98527584 | P8: 0.95520401 | Q8: 0.98143122 | R8: 0.73013245 | S8: 0.71551724 | U8: 0.99629524 | Z8: 0.97808797 | AA8: 0.99442796 | AB8: 0.90492476 | AC8: 0.89247312 | AE8: 0.98889895 | AF8: =IFERROR(AVERAGE(L8:U8),"") | AG8: =IFERROR(AVERAGE(V8:AE8),"") | AH8: =IFERROR(AVERAGE(B8:K8),"") | AI8: 0.98767471 | AJ8: 0
A9: 6371.jpg | F9: 0.94905839 | G9: 0.96161988 | H9: 0 | K9: 0.97978414 | P9: 0.993609 | Q9: 0.97639519 | R9: 0 | U9: 0.99091581 | Z9: 0.95488745 | AA9: 0.98450732 | AE9: 0.98866446 | AF9: =IFERROR(AVERAGE(L9:U9),"") | AG9: =IFERROR(AVERAGE(V9:AE9),"") | AH9: =IFERROR(AVERAGE(B9:K9),"") | AI9: 0.98407364 | AJ9: 0
A10: 6377.jpg | F10: 0.95256481 | G10: 0.9566784 | I10: 0.71578947 | K10: 0.98513387 | P10: 0.9661421 | Q10: 0.98903611 | S10: 0.75836431 | U10: 0.99330422 | Z10: 0.98546158 | AA10: 0.96693291 | AC10: 0.92727273 | AE10: 0.99171959 | AF10: =IFERROR(AVERAGE(L10:U10),"") | AG10: =IFERROR(AVERAGE(V10:AE10),"") | AH10: =IFERROR(AVERAGE(B10:K10),"") | AI10: 0.98841858 | AJ10: 0
A11: 6383.jpg | F11: 0.93522755 | G11: 0.95640048 | I11: 0.56967213 | K11: 0.98612815 | P11: 0.95311466 | Q11: 0.99482667 | S11: 0.76373626 | U11: 0.99334262 | Z11: 0.98032798 | AA11: 0.96118092 | AC11: 0.69154229 | AE11: 0.99268886 | AF11: =IFERROR(AVERAGE(L11:U11),"") | AG11: =IFERROR(AVERAGE(V11:AE11),"") | AH11: =IFERROR(AVERAGE(B11:K11),"") | AI11: 0.98843002 | AJ11: 0
A12: 6389.jpg | F12: 0.92860143 | G12: 0.94355857 | I12: 0 | K12: 0.97964487 | P12: 0.97952252 | Q12: 0.99477421 | S12: 0 | U12: 0.98421485 | Z12: 0.9469852 | AA12: 0.94825885 | AE12: 0.99528262 | AF12: =IFERROR(AVERAGE(L12:U12),"") | AG12: =IFERROR(AVERAGE(V12:AE12),"") | AH12: =IFERROR(AVERAGE(B12:K12),"") | AI12: 0.98372269 | AJ12: 0
A13: 6391.jpg | F13: 0.93659051 | G13: 0.9466699 | K13: 0.98004282 | P13: 0.96060511 | Q13: 0.98801881 | U13: 0.98988082 | Z13: 0.97400196 | AA13: 0.95766366 | AE13: 0.98996084 | AF13: =IFERROR(AVERAGE(L13:U13),"") | AG13: =IFERROR(AVERAGE(V13:AE13),"") | AH13: =IFERROR(AVERAGE(B13:K13),"") | AI13: 0.98477936 | AJ13: 0
A14: 6394.jpg | F14: 0.78690381 | G14: 0.95507383 | I14: 0 | K14: 0.93239687 | P14: 0.97194365 | Q14: 0.98413726 | S14: 0 | U14: 0.93964464 | Z14: 0.80519375 | AA14: 0.97000638 | AE14: 0.99179532 | AF14: =IFERROR(AVERAGE(L14:U14),"") | AG14: =IFERROR(AVERAGE(V14:AE14),"") | AH14: =IFERROR(AVERAGE(B14:K14),"") | AI14: 0.94740295 | AJ14: 0
A15: 6405.jpg | F15: 0.9232102 | G15: 0.93094945 | K15: 0.98728526 | P15: 0.92389622 | Q15: 0.95108814 | U15: 0.99771274 | Z15: 0.99919636 | AA15: 0.97776091 | AE15: 0.98952491 | AF15: =IFERROR(AVERAGE(L15:U15),"") | AG15: =IFERROR(AVERAGE(V15:AE15),"") | AH15: =IFERROR(AVERAGE(B15:K15),"") | AI15: 0.98907089 | AJ15: 0
A16: 6412.jpg | C16: 0 | D16: 0 | F16: 0.88990663 | G16: 0 | H16: 0.76455651 | I16: 0.73509015 | J16: 0.86414649 | K16: 0.90229036 | N16: 0 | P16: 0.89871067 | Q16: 0 | R16: 0.86468977 | S16: 0.87171053 | T16: 0.90532178 | U16: 0.95437421 | W16: 0 | Z16: 0.98911164 | AB16: 0.86845989 | AC16: 0.82426128 | AD16: 0.95 | AE16: 0.94296597 | AF16: =IFERROR(AVERAGE(L16:U16),"") | AG16: =IFERROR(AVERAGE(V16:AE16),"") | AH16: =IFERROR(AVERAGE(B16:K16),"") | AI16: 0.70100021 | AJ16: 0
A17: 6417.jpg | D17: 0.87527829 | F17: 0.8912822 | G17: 0.8960396 | H17: 0.92081686 | I17: 0.78243612 | J17: 0.88858696 | K17: 0.90308113 | N17: 0.89203498 | P17: 0.92003756 | Q17: 0.95117145 | R17: 0.96428225 | S17: 0.80010147 | T17: 0.96176471 | U17: 0.96047452 | X17: 0.97898942 | Z17: 0.96612108 | AA17: 0.93924324 | AB17: 0.95333291 | AC17: 0.97255628 | AD17: 0.92112676 | AE17: 0.93793832 | AF17: =IFERROR(AVERAGE(L17:U17),"") | AG17: =IFERROR(AVERAGE(V17:AE17),"") | AH17: =IFERROR(AVERAGE(B17:K17),"") | AI17: 0.94961929 | AJ17: 0
A18: 6419.jpg | D18: 0.88551009 | F18: 0.87557604 | G18: 0.5327674 | H18: 0.87814868 | I18: 0.82873082 | K18: 0.91867047 | N18: 0.94508091 | P18: 0.89917791 | Q18: 1 | R18: 0.9410904 | S18: 0.86240929 | U18: 0.96088386 | X18: 0.93354804 | Z18: 0.97089424 | AA18: 0.5327674 | AB18: 0.92922799 | AC18: 0.95499839 | AE18: 0.95436139 | AF18: =IFERROR(AVERAGE(L18:U18),"") | AG18: =IFERROR(AVERAGE(V18:AE18),"") | AH18: =IFERROR(AVERAGE(B18:K18),"") | AI18: 0.94403076 | AJ18: 0
A19: 6420.jpg | D19: 0.84205986 | F19: 0.91940927 | G19: 0.33726736 | H19: 0.8715148 | I19: 0.85175664 | K19: 0.92190162 | N19: 0.90150177 | P19: 0.93687805 | Q19: 1 | R19: 0.95071031 | S19: 0.86660854 | U19: 0.95280286 | X19: 0.92738238 | Z19: 0.98012299 | AA19: 0.33726736 | AB19: 0.9127566 | AC19: 0.98027613 | AE19: 0.96601615 | AF19: =IFERROR(AVERAGE(L19:U19),"") | AG19: =IFERROR(AVERAGE(V19:AE19),"") | AH19: =IFERROR(AVERAGE(B19:K19),"") | AI19: 0.94464111 | AJ19: 0
A20: 6445.jpg | D20: 0.85326537 | F20: 0.22091537 | G20: 0.99153578 | H20: 0.65847532 | I20: 0.70349762 | J20: 0.86205396 | K20: 0.91923291 | N20: 0.87850595 | P20: 0.66976744 | Q20: 0.99284885 | R20: 0.80231596 | S20: 0.7381151 | T20: 0.92011147 | U20: 0.96233276 | X20: 0.96742475 | Z20: 0.24791966 | AA20: 0.99866795 | AB20: 0.78599789 | AC20: 0.9375 | AD20: 0.9317968 | AE20: 0.95354157 | AF20: =IFERROR(AVERAGE(L20:U20),"") | AG20: =IFERROR(AVERAGE(V20:AE20),"") | AH20: =IFERROR(AVERAGE(B20:K20),"") | AI20: 0.95096207 | AJ20: 0
A21: 6449.jpg | D21: 0.84242298 | G21: 0.9965557 | H21: 0.87808563 | J21: 0.66131237 | K21: 0.95938715 | N21: 0.98563078 | Q21: 0.99776132 | R21: 0.9264317 | T21: 0.82904884 | U21: 0.97613356 | X21: 0.85289779 | AA21: 0.99878896 | AB21: 0.94390316 | AD21: 0.76573011 | AE21: 0.98243204 | AF21: =IFERROR(AVERAGE(L21:U21),"") | AG21: =IFERROR(AVERAGE(V21:AE21),"") | AH21: =IFERROR(AVERAGE(B21:K21),"") | AI21: 0.9771843 | AJ21: 0
A22: 6452.jpg | D22: 0.78371106 | G22: 0.99571134 | H22: 0.85581395 | I22: 0 | J22: 0.83579639 | K22: 0.93771241 | N22: 0.99136013 | Q22: 0.99985077 | R22: 0.90819348 | T22: 0.85223943 | U22: 0.94661878 | X22: 0.78910076 | AA22: 0.99585935 | AB22: 0.93686354 | AC22: 0 | AD22: 0.97743639 | AE22: 0.99006609 | AF22: =IFERROR(AVERAGE(L22:U22),"") | AG22: =IFERROR(AVERAGE(V22:AE22),"") | AH22: =IFERROR(AVERAGE(B22:K22),"") | AI22: 0.96693802 | AJ22: 0
A23: 6467.jpg | D23: 0.87335775 | F23: 0.80368242 | G23: 0.91580795 | H23: 0.8172353 | I23: 0.78701456 | J23: 0.68332751 | K23: 0.84544738 | N23: 0.93121702 | P23: 0.84693814 | Q23: 0.98400722 | R23: 0.90839491 | S23: 0.81726528 | T23: 0.74325181 | U23: 0.92295243 | X23: 0.9335825 | Z23: 0.94024834 | AA23: 0.92964513 | AB23: 0.89063455 | AC23: 0.955081 | AD23: 0.89446393 | AE23: 0.90964806 | AF23: =IFERROR(AVERAGE(L23:U23),"") | AG23: =IFERROR(AVERAGE(V23:AE23),"") | AH23: =IFERROR(AVERAGE(B23:K23),"") | AI23: 0.91450882 | AJ23: 0
A24: 6468.jpg | D24: 0.84995867 | F24: 0.74573768 | G24: 0.97370586 | H24: 0.75685164 | I24: 0.76240668 | J24: 0.67373131 | K24: 0.87151532 | N24: 0.89004893 | P24: 0.79085991 | Q24: 0.9817821 | R24: 0.85609975 | S24: 0.78623188 | T24: 0.70641975 | U24: 0.95842873 | X24: 0.94967297 | Z24: 0.92892977 | AA24: 0.99162254 | AB24: 0.86717128 | AC24: 0.96177285 | AD24: 0.93573181 | AE24: 0.90575414 | AF24: =IFERROR(AVERAGE(L24:U24),"") | AG24: =IFERROR(AVERAGE(V24:AE24),"") | AH24: =IFERROR(AVERAGE(B24:K24),"") | AI24: 0.92380142 | AJ24: 0
A25: 6476.jpg | D25: 0.71015908 | F25: 0 | G25: 0.94821327 | H25: 0.90473233 | I25: 0 | J25: 0.42887029 | K25: 0.89717984 | N25: 0.79309903 | P25: 0 | Q25: 0.97499177 | R25: 0.94145017 | S25: 0 | T25: 0.53246753 | U25: 0.95979642 | X25: 0.87164305 | AA25: 0.97185 | AB25: 0.95867334 | AD25: 0.68791946 | AE25: 0.93221308 | AF25: =IFERROR(AVERAGE(L25:U25),"") | AG25: =IFERROR(AVERAGE(V25:AE25),"") | AH25: =IFERROR(AVERAGE(B25:K25),"") | AI25: 0.94388199 | AJ25: 0
A26: 6488.jpg | D26: 0.6813027 | F26: 0 | G26: 0.98460698 | H26: 0.89822675 | K26: 0.9675708 | N26: 0.81128809 | P26: 0 | Q26: 0.99078653 | R26: 0.94048395 | U26: 0.98573596 | X26: 0.80960608 | AA26: 0.99370536 | AB26: 0.95236076 | AE26: 0.9813103 | AF26: =IFERROR(AVERAGE(L26:U26),"") | AG26: =IFERROR(AVERAGE(V26:AE26),"") | AH26: =IFERROR(AVERAGE(B26:K26),"") | AI26: 0.98153305 | AJ26: 0
A27: 6514.jpg | D27: 0.7737945 | G27: 0 | H27: 0.97668535 | K27: 0.91642949 | N27: 0.82843435 | Q27: 0 | R27: 0.98903388 | U27: 0.97119544 | X27: 0.9214581 | AB27: 0.98737787 | AE27: 0.94203422 | AF27: =IFERROR(AVERAGE(L27:U27),"") | AG27: =IFERROR(AVERAGE(V27:AE27),"") | AH27: =IFERROR(AVERAGE(B27:K27),"") | AI27: 0.9691925 | AJ27: 0
A28: 6517.jpg | D28: 0.78215419 | G28: 0.55298176 | H28: 0.97394205 | K28: 0.89488512 | N28: 0.88997451 | Q28: 0.67427885 | R28: 0.98482886 | U28: 0.94663505 | X28: 0.86588138 | AA28: 0.75453934 | AB28: 0.98877711 | AE28: 0.9424284 | AF28: =IFERROR(AVERAGE(L28:U28),"") | AG28: =IFERROR(AVERAGE(V28:AE28),"") | AH28: =IFERROR(AVERAGE(B28:K28),"") | AI28: 0.96136856 | AJ28: 0
A29: 6536.jpg | D29: 0 | F29: 0.89136165 | G29: 0.33270844 | H29: 0.87217568 | I29: 0.82802548 | K29: 0.81044983 | N29: 0 | P29: 0.93067431 | Q29: 0.64622461 | R29: 0.90141537 | S29: 0.85997795 | U29: 0.91600924 | Z29: 0.9547548 | AA29: 0.4068042 | AB29: 0.9641421 | AC29: 0.95705521 | AE29: 0.8755106 | AF29: =IFERROR(AVERAGE(L29:U29),"") | AG29: =IFERROR(AVERAGE(V29:AE29),"") | AH29: =IFERROR(AVERAGE(B29:K29),"") | AI29: 0.89777756 | AJ29: 0
A30: 6545.jpg | D30: 0.93676399 | G30: 0.77180287 | H30: 0.97178701 | K30: 0.95111335 | N30: 0.95009817 | Q30: 0.80005173 | R30: 0.99618478 | U30: 0.95914076 | X30: 0.98523923 | AA30: 0.9562529 | AB30: 0.9754173 | AE30: 0.9912772 | AF30: =IFERROR(AVERAGE(L30:U30),"") | AG30: =IFERROR(AVERAGE(V30:AE30),"") | AH30: =IFERROR(AVERAGE(B30:K30),"") | AI30: 0.9793129 | AJ30: 0
A31: 6550.jpg | F31: 0.7162692 | G31: 0.78763146 | H31: 0.79159782 | K31: 0.79911596 | P31: 0.94372189 | Q31: 0.95887093 | R31: 0.82056473 | U31: 0.90861993 | Z31: 0.74822917 | AA31: 0.81517125 | AB31: 0.95730895 | AE31: 0.86895116 | AF31: =IFERROR(AVERAGE(L31:U31),"") | AG31: =IFERROR(AVERAGE(V31:AE31),"") | AH31: =IFERROR(AVERAGE(B31:K31),"") | AI31: 0.88234329 | AJ31: 0
A32: 6553.jpg | D32: 0.71877768 | G32: 0.84517791 | H32: 0.90100458 | J32: 0.6812065 | K32: 0.86379143 | N32: 0.80907278 | Q32: 0.96583713 | R32: 0.9606844 | T32: 0.68791003 | U32: 0.90771558 | X32: 0.8656 | AA32: 0.87122313 | AB32: 0.93549946 | AD32: 0.98589657 | AE32: 0.94695158 | AF32: =IFERROR(AVERAGE(L32:U32),"") | AG32: =IFERROR(AVERAGE(V32:AE32),"") | AH32: =IFERROR(AVERAGE(B32:K32),"") | AI32: 0.93445969 | AJ32: 0
A33: 6557.jpg | D33: 0.87407145 | F33: 0 | G33: 0.90408958 | H33: 0.91076863 | I33: 0.51696284 | J33: 0.85595855 | K33: 0.87670616 | N33: 0.9179049 | P33: 0 | Q33: 0.95172202 | R33: 0.94580329 | S33: 0.92485549 | T33: 0.92238973 | U33: 0.9528274 | X33: 0.94819647 | AA33: 0.94754567 | AB33: 0.96091812 | AC33: 0.53962901 | AD33: 0.92238973 | AE33: 0.91648527 | AF33: =IFERROR(AVERAGE(L33:U33),"") | AG33: =IFERROR(AVERAGE(V33:AE33),"") | AH33: =IFERROR(AVERAGE(B33:K33),"") | AI33: 0.93936539 | AJ33: 0
A34: 6558.jpg | D34: 0.8907221 | F34: 0 | G34: 0.85328836 | H34: 0.90870283 | I34: 0.6512301 | J34: 0.62622761 | K34: 0.85074739 | N34: 0.92792483 | P34: 0 | Q34: 0.92335766 | R34: 0.93436243 | S34: 0.96359743 | T34: 0.74604267 | U34: 0.96415781 | X34: 0.95692762 | AA34: 0.91833031 | AB34: 0.97066527 | AC34: 0.66765579 | AD34: 0.7958884 | AE34: 0.87853202 | AF34: =IFERROR(AVERAGE(L34:U34),"") | AG34: =IFERROR(AVERAGE(V34:AE34),"") | AH34: =IFERROR(AVERAGE(B34:K34),"") | AI34: 0.92551041 | AJ34: 0
A35: 6561.jpg | D35: 0.84701414 | F35: 0.86472862 | G35: 0.62796135 | H35: 0.91228317 | I35: 0.64140969 | J35: 0.62578616 | K35: 0.78400369 | N35: 0.92627207 | P35: 0.9132904 | Q35: 0.88568916 | R35: 0.95378651 | S35: 0.92738854 | T35: 0.97389886 | U35: 0.87382814 | X35: 0.90824754 | Z35: 0.94207182 | AA35: 0.68334464 | AB35: 0.95447331 | AC35: 0.67532468 | AD35: 0.63646055 | AE35: 0.88408387 | AF35: =IFERROR(AVERAGE(L35:U35),"") | AG35: =IFERROR(AVERAGE(V35:AE35),"") | AH35: =IFERROR(AVERAGE(B35:K35),"") | AI35: 0.9236412 | AJ35: 0
A36: 6562.jpg | D36: 0.85555139 | F36: 0.88868797 | G36: 0.59246003 | H36: 0.90488105 | I36: 0.61255116 | J36: 0.85971223 | K36: 0.80728263 | N36: 0.96842217 | P36: 0.91946572 | Q36: 0.99598877 | R36: 0.91947562 | S36: 0.73970346 | T36: 0.95219124 | U36: 0.94198488 | X36: 0.88010401 | Z36: 0.96370104 | AA36: 0.59387706 | AB36: 0.98276118 | AC36: 0.78086957 | AD36: 0.89849624 | AE36: 0.84951996 | AF36: =IFERROR(AVERAGE(L36:U36),"") | AG36: =IFERROR(AVERAGE(V36:AE36),"") | AH36: =IFERROR(AVERAGE(B36:K36),"") | AI36: 0.9280777 | AJ36: 0
A37: 6567.jpg | D37: 0.8794604 | F37: 0.90056338 | H37: 0.96009592 | I37: 0 | K37: 0.9226894 | N37: 0.89882144 | P37: 0.99101054 | R37: 0.98605994 | S37: 0 | U37: 0.9575672 | X37: 0.97609273 | Z37: 0.90798069 | AB37: 0.97330661 | AE37: 0.96202391 | AF37: =IFERROR(AVERAGE(L37:U37),"") | AG37: =IFERROR(AVERAGE(V37:AE37),"") | AH37: =IFERROR(AVERAGE(B37:K37),"") | AI37: 0.96876526 | AJ37: 0
A38: 6568.jpg | D38: 0.89108341 | F38: 0.93144638 | H38: 0.92713044 | I38: 0.74202128 | J38: 0.88023256 | K38: 0.90824024 | N38: 0.91487474 | P38: 0.97951939 | R38: 0.96815841 | S38: 0.77932961 | T38: 0.92204629 | U38: 0.95056995 | X38: 0.97164393 | Z38: 0.94994703 | AB38: 0.95628985 | AC38: 0.93939394 | AD38: 0.95100503 | AE38: 0.95326173 | AF38: =IFERROR(AVERAGE(L38:U38),"") | AG38: =IFERROR(AVERAGE(V38:AE38),"") | AH38: =IFERROR(AVERAGE(B38:K38),"") | AI38: 0.95615768 | AJ38: 0
A39: 6583.jpg | B39: 0 | G39: 0.91269182 | H39: 0.95531832 | K39: 0.97112851 | L39: 0 | Q39: 0.97110915 | R39: 0.9948459 | U39: 0.97952452 | AA39: 0.93816576 | AB39: 0.96007001 | AE39: 0.99125087 | AF39: =IFERROR(AVERAGE(L39:U39),"") | AG39: =IFERROR(AVERAGE(V39:AE39),"") | AH39: =IFERROR(AVERAGE(B39:K39),"") | AI39: 0.97634888 | AJ39: 0
A40: 6590.jpg | G40: 0.8580816 | I40: 0 | K40: 0.97464015 | Q40: 0.9105926 | S40: 0 | U40: 0.98971168 | AA40: 0.93702764 | AE40: 0.98461593 | AF40: =IFERROR(AVERAGE(L40:U40),"") | AG40: =IFERROR(AVERAGE(V40:AE40),"") | AH40: =IFERROR(AVERAGE(B40:K40),"") | AI40: 0.97796249 | AJ40: 0
...

Sheet YOLO11n-seg
A1: YOLO11n-seg — métricas por imagen de test (426 imágenes)
A2: Celdas vacías: la clase no aparece ni en la referencia ni en la predicción (IoU), no se predice (precisión) o no está en la referencia (recall). Ver la hoja Léeme.
B3: IoU por clase | L3: Precisión por clase | V3: Recall por clase | AF3: Resumen de la imagen
A4: Imagen | B4: IoU Background | C4: IoU Building-flooded | D4: IoU Building-non-flooded | E4: IoU Road-flooded | F4: IoU Road-non-flooded | G4: IoU Water | H4: IoU Tree | I4: IoU Vehicle | J4: IoU Pool | K4: IoU Grass | L4: Precisión Background | M4: Precisión Building-flooded | N4: Precisión Building-non-flooded | O4: Precisión Road-flooded | P4: Precisión Road-non-flooded | Q4: Precisión Water | R4: Precisión Tree | S4: Precisión Vehicle | T4: Precisión Pool | U4: Precisión Grass | V4: Recall Background | W4: Recall Building-flooded | X4: Recall Building-non-flooded | Y4: Recall Road-flooded | Z4: Recall Road-non-flooded | AA4: Recall Water | AB4: Recall Tree | AC4: Recall Vehicle | AD4: Recall Pool | AE4: Recall Grass | AF4: Precisión | AG4: Recall | AH4: Mean_IoU | AI4: Pixel accuracy | AJ4: % píxeles sin predicción
A5: 6336.jpg | F5: 0.91531931 | G5: 0.86246982 | I5: 0.85089141 | K5: 0.95484256 | P5: 0.96632892 | Q5: 0.88203538 | S5: 0.87209302 | U5: 0.98565315 | Z5: 0.94547396 | AA5: 0.97492541 | AC5: 0.97222222 | AE5: 0.96830037 | AF5: =IFERROR(AVERAGE(L5:U5),"") | AG5: =IFERROR(AVERAGE(V5:AE5),"") | AH5: =IFERROR(AVERAGE(B5:K5),"") | AI5: 0.96299744 | AJ5: 0.010940552
A6: 6342.jpg | F6: 0.93516068 | G6: 0.92680358 | K6: 0.96303767 | P6: 0.96352254 | Q6: 0.99257449 | U6: 0.98505509 | Z6: 0.96948403 | AA6: 0.93327441 | AE6: 0.97731712 | AF6: =IFERROR(AVERAGE(L6:U6),"") | AG6: =IFERROR(AVERAGE(V6:AE6),"") | AH6: =IFERROR(AVERAGE(B6:K6),"") | AI6: 0.97054672 | AJ6: 0.01266098
A7: 6353.jpg | F7: 0.89967796 | G7: 0.92284952 | H7: 0.78567368 | K7: 0.96453743 | P7: 0.94360987 | Q7: 0.97266908 | R7: 0.84525994 | U7: 0.98767079 | Z7: 0.95079736 | AA7: 0.94741704 | AB7: 0.91766268 | AE7: 0.97629241 | AF7: =IFERROR(AVERAGE(L7:U7),"") | AG7: =IFERROR(AVERAGE(V7:AE7),"") | AH7: =IFERROR(AVERAGE(B7:K7),"") | AI7: 0.96961594 | AJ7: 0.010379791
A8: 6362.jpg | F8: 0.95277875 | G8: 0.96225487 | H8: 0.65502793 | I8: 0.6872428 | K8: 0.97424343 | P8: 0.98166886 | Q8: 0.97105972 | R8: 0.6722408 | S8: 0.74553571 | U8: 0.99826856 | Z8: 0.97003733 | AA8: 0.99066503 | AB8: 0.9623803 | AC8: 0.89784946 | AE8: 0.97589246 | AF8: =IFERROR(AVERAGE(L8:U8),"") | AG8: =IFERROR(AVERAGE(V8:AE8),"") | AH8: =IFERROR(AVERAGE(B8:K8),"") | AI8: 0.97663116 | AJ8: 0.013988495
A9: 6371.jpg | F9: 0.93715822 | G9: 0.90664125 | K9: 0.97205093 | P9: 0.98301379 | Q9: 0.92942799 | U9: 0.9936467 | Z9: 0.95258422 | AA9: 0.97367048 | AE9: 0.97813022 | AF9: =IFERROR(AVERAGE(L9:U9),"") | AG9: =IFERROR(AVERAGE(V9:AE9),"") | AH9: =IFERROR(AVERAGE(B9:K9),"") | AI9: 0.97453308 | AJ9: 0.011512756
A10: 6377.jpg | F10: 0.9544118 | G10: 0.95887201 | I10: 0.83333333 | K10: 0.97213321 | P10: 0.97896259 | Q10: 0.97578424 | S10: 0.95959596 | U10: 0.99471066 | Z10: 0.97439651 | AA10: 0.98224558 | AC10: 0.86363636 | AE10: 0.97718456 | AF10: =IFERROR(AVERAGE(L10:U10),"") | AG10: =IFERROR(AVERAGE(V10:AE10),"") | AH10: =IFERROR(AVERAGE(B10:K10),"") | AI10: 0.97712708 | AJ10: 0.013462067
A11: 6383.jpg | F11: 0.94491406 | G11: 0.9665509 | I11: 0.81042654 | K11: 0.97934563 | P11: 0.96180467 | Q11: 0.97794628 | S11: 0.94475138 | U11: 0.99784222 | Z11: 0.98175395 | AA11: 0.98808801 | AC11: 0.85074627 | AE11: 0.98142407 | AF11: =IFERROR(AVERAGE(L11:U11),"") | AG11: =IFERROR(AVERAGE(V11:AE11),"") | AH11: =IFERROR(AVERAGE(B11:K11),"") | AI11: 0.98190689 | AJ11: 0.0099487305
